[2024-05-26 16:06:01,308] {taskinstance.py:851} INFO - Dependencies all met for <TaskInstance: get_new_data.scrap_cnn 2024-05-13T00:00:00+00:00 [queued]>
[2024-05-26 16:06:01,328] {taskinstance.py:851} INFO - Dependencies all met for <TaskInstance: get_new_data.scrap_cnn 2024-05-13T00:00:00+00:00 [queued]>
[2024-05-26 16:06:01,330] {taskinstance.py:1042} INFO - 
--------------------------------------------------------------------------------
[2024-05-26 16:06:01,332] {taskinstance.py:1043} INFO - Starting attempt 1 of 6
[2024-05-26 16:06:01,335] {taskinstance.py:1044} INFO - 
--------------------------------------------------------------------------------
[2024-05-26 16:06:01,360] {taskinstance.py:1063} INFO - Executing <Task(PythonOperator): scrap_cnn> on 2024-05-13T00:00:00+00:00
[2024-05-26 16:06:01,364] {standard_task_runner.py:52} INFO - Started process 194 to run task
[2024-05-26 16:06:01,368] {standard_task_runner.py:76} INFO - Running: ['airflow', 'tasks', 'run', 'get_new_data', 'scrap_cnn', '2024-05-13T00:00:00+00:00', '--job-id', '25', '--pool', 'default_pool', '--raw', '--subdir', 'DAGS_FOLDER/get_new_data.py', '--cfg-path', '/tmp/tmpn295guts', '--error-file', '/tmp/tmp1rlk62ax']
[2024-05-26 16:06:01,371] {standard_task_runner.py:77} INFO - Job 25: Subtask scrap_cnn
[2024-05-26 16:06:01,413] {logging_mixin.py:104} INFO - Running <TaskInstance: get_new_data.scrap_cnn 2024-05-13T00:00:00+00:00 [running]> on host 6a7718113559
[2024-05-26 16:06:01,445] {taskinstance.py:1257} INFO - Exporting the following env vars:
AIRFLOW_CTX_DAG_OWNER=airflow
AIRFLOW_CTX_DAG_ID=get_new_data
AIRFLOW_CTX_TASK_ID=scrap_cnn
AIRFLOW_CTX_EXECUTION_DATE=2024-05-13T00:00:00+00:00
AIRFLOW_CTX_DAG_RUN_ID=scheduled__2024-05-13T00:00:00+00:00
[2024-05-26 16:06:01,461] {taskinstance.py:1455} ERROR - HTTPConnectionPool(host='localhost', port=7010): Max retries exceeded with url: /extract_news (Caused by NewConnectionError('<urllib3.connection.HTTPConnection object at 0x7fffafddba58>: Failed to establish a new connection: [Errno 111] Connection refused',))
Traceback (most recent call last):
  File "/home/airflow/.local/lib/python3.6/site-packages/urllib3/connection.py", line 160, in _new_conn
    (self._dns_host, self.port), self.timeout, **extra_kw
  File "/home/airflow/.local/lib/python3.6/site-packages/urllib3/util/connection.py", line 84, in create_connection
    raise err
  File "/home/airflow/.local/lib/python3.6/site-packages/urllib3/util/connection.py", line 74, in create_connection
    sock.connect(sa)
ConnectionRefusedError: [Errno 111] Connection refused

During handling of the above exception, another exception occurred:

Traceback (most recent call last):
  File "/home/airflow/.local/lib/python3.6/site-packages/urllib3/connectionpool.py", line 677, in urlopen
    chunked=chunked,
  File "/home/airflow/.local/lib/python3.6/site-packages/urllib3/connectionpool.py", line 392, in _make_request
    conn.request(method, url, **httplib_request_kw)
  File "/usr/local/lib/python3.6/http/client.py", line 1291, in request
    self._send_request(method, url, body, headers, encode_chunked)
  File "/usr/local/lib/python3.6/http/client.py", line 1337, in _send_request
    self.endheaders(body, encode_chunked=encode_chunked)
  File "/usr/local/lib/python3.6/http/client.py", line 1286, in endheaders
    self._send_output(message_body, encode_chunked=encode_chunked)
  File "/usr/local/lib/python3.6/http/client.py", line 1046, in _send_output
    self.send(msg)
  File "/usr/local/lib/python3.6/http/client.py", line 984, in send
    self.connect()
  File "/home/airflow/.local/lib/python3.6/site-packages/urllib3/connection.py", line 187, in connect
    conn = self._new_conn()
  File "/home/airflow/.local/lib/python3.6/site-packages/urllib3/connection.py", line 172, in _new_conn
    self, "Failed to establish a new connection: %s" % e
urllib3.exceptions.NewConnectionError: <urllib3.connection.HTTPConnection object at 0x7fffafddba58>: Failed to establish a new connection: [Errno 111] Connection refused

During handling of the above exception, another exception occurred:

Traceback (most recent call last):
  File "/home/airflow/.local/lib/python3.6/site-packages/requests/adapters.py", line 449, in send
    timeout=timeout
  File "/home/airflow/.local/lib/python3.6/site-packages/urllib3/connectionpool.py", line 727, in urlopen
    method, url, error=e, _pool=self, _stacktrace=sys.exc_info()[2]
  File "/home/airflow/.local/lib/python3.6/site-packages/urllib3/util/retry.py", line 446, in increment
    raise MaxRetryError(_pool, url, error or ResponseError(cause))
urllib3.exceptions.MaxRetryError: HTTPConnectionPool(host='localhost', port=7010): Max retries exceeded with url: /extract_news (Caused by NewConnectionError('<urllib3.connection.HTTPConnection object at 0x7fffafddba58>: Failed to establish a new connection: [Errno 111] Connection refused',))

During handling of the above exception, another exception occurred:

Traceback (most recent call last):
  File "/home/airflow/.local/lib/python3.6/site-packages/airflow/models/taskinstance.py", line 1112, in _run_raw_task
    self._prepare_and_execute_task_with_callbacks(context, task)
  File "/home/airflow/.local/lib/python3.6/site-packages/airflow/models/taskinstance.py", line 1285, in _prepare_and_execute_task_with_callbacks
    result = self._execute_task(context, task_copy)
  File "/home/airflow/.local/lib/python3.6/site-packages/airflow/models/taskinstance.py", line 1315, in _execute_task
    result = task_copy.execute(context=context)
  File "/home/airflow/.local/lib/python3.6/site-packages/airflow/operators/python.py", line 117, in execute
    return_value = self.execute_callable()
  File "/home/airflow/.local/lib/python3.6/site-packages/airflow/operators/python.py", line 128, in execute_callable
    return self.python_callable(*self.op_args, **self.op_kwargs)
  File "/opt/airflow/dags/get_new_data.py", line 17, in scrap_cnn
    response = requests.get('http://localhost:7010/extract_news')
  File "/home/airflow/.local/lib/python3.6/site-packages/requests/api.py", line 76, in get
    return request('get', url, params=params, **kwargs)
  File "/home/airflow/.local/lib/python3.6/site-packages/requests/api.py", line 61, in request
    return session.request(method=method, url=url, **kwargs)
  File "/home/airflow/.local/lib/python3.6/site-packages/requests/sessions.py", line 542, in request
    resp = self.send(prep, **send_kwargs)
  File "/home/airflow/.local/lib/python3.6/site-packages/requests/sessions.py", line 655, in send
    r = adapter.send(request, **kwargs)
  File "/home/airflow/.local/lib/python3.6/site-packages/requests/adapters.py", line 516, in send
    raise ConnectionError(e, request=request)
requests.exceptions.ConnectionError: HTTPConnectionPool(host='localhost', port=7010): Max retries exceeded with url: /extract_news (Caused by NewConnectionError('<urllib3.connection.HTTPConnection object at 0x7fffafddba58>: Failed to establish a new connection: [Errno 111] Connection refused',))
[2024-05-26 16:06:01,468] {taskinstance.py:1503} INFO - Marking task as UP_FOR_RETRY. dag_id=get_new_data, task_id=scrap_cnn, execution_date=20240513T000000, start_date=20240526T160601, end_date=20240526T160601
[2024-05-26 16:06:01,509] {local_task_job.py:146} INFO - Task exited with return code 1
[2024-05-26 16:21:01,737] {taskinstance.py:851} INFO - Dependencies all met for <TaskInstance: get_new_data.scrap_cnn 2024-05-13T00:00:00+00:00 [queued]>
[2024-05-26 16:21:01,748] {taskinstance.py:851} INFO - Dependencies all met for <TaskInstance: get_new_data.scrap_cnn 2024-05-13T00:00:00+00:00 [queued]>
[2024-05-26 16:21:01,749] {taskinstance.py:1042} INFO - 
--------------------------------------------------------------------------------
[2024-05-26 16:21:01,750] {taskinstance.py:1043} INFO - Starting attempt 1 of 6
[2024-05-26 16:21:01,751] {taskinstance.py:1044} INFO - 
--------------------------------------------------------------------------------
[2024-05-26 16:21:01,765] {taskinstance.py:1063} INFO - Executing <Task(PythonOperator): scrap_cnn> on 2024-05-13T00:00:00+00:00
[2024-05-26 16:21:01,770] {standard_task_runner.py:52} INFO - Started process 199 to run task
[2024-05-26 16:21:01,776] {standard_task_runner.py:76} INFO - Running: ['airflow', 'tasks', 'run', 'get_new_data', 'scrap_cnn', '2024-05-13T00:00:00+00:00', '--job-id', '109', '--pool', 'default_pool', '--raw', '--subdir', 'DAGS_FOLDER/get_new_data.py', '--cfg-path', '/tmp/tmphq1al3xb', '--error-file', '/tmp/tmpef33h6t5']
[2024-05-26 16:21:01,783] {standard_task_runner.py:77} INFO - Job 109: Subtask scrap_cnn
[2024-05-26 16:21:01,823] {logging_mixin.py:104} INFO - Running <TaskInstance: get_new_data.scrap_cnn 2024-05-13T00:00:00+00:00 [running]> on host 6a7718113559
[2024-05-26 16:21:01,859] {taskinstance.py:1257} INFO - Exporting the following env vars:
AIRFLOW_CTX_DAG_OWNER=airflow
AIRFLOW_CTX_DAG_ID=get_new_data
AIRFLOW_CTX_TASK_ID=scrap_cnn
AIRFLOW_CTX_EXECUTION_DATE=2024-05-13T00:00:00+00:00
AIRFLOW_CTX_DAG_RUN_ID=scheduled__2024-05-13T00:00:00+00:00
[2024-05-26 16:21:01,868] {taskinstance.py:1455} ERROR - HTTPConnectionPool(host='localhost', port=7010): Max retries exceeded with url: /extract_news (Caused by NewConnectionError('<urllib3.connection.HTTPConnection object at 0x7fffafddc978>: Failed to establish a new connection: [Errno 111] Connection refused',))
Traceback (most recent call last):
  File "/home/airflow/.local/lib/python3.6/site-packages/urllib3/connection.py", line 160, in _new_conn
    (self._dns_host, self.port), self.timeout, **extra_kw
  File "/home/airflow/.local/lib/python3.6/site-packages/urllib3/util/connection.py", line 84, in create_connection
    raise err
  File "/home/airflow/.local/lib/python3.6/site-packages/urllib3/util/connection.py", line 74, in create_connection
    sock.connect(sa)
ConnectionRefusedError: [Errno 111] Connection refused

During handling of the above exception, another exception occurred:

Traceback (most recent call last):
  File "/home/airflow/.local/lib/python3.6/site-packages/urllib3/connectionpool.py", line 677, in urlopen
    chunked=chunked,
  File "/home/airflow/.local/lib/python3.6/site-packages/urllib3/connectionpool.py", line 392, in _make_request
    conn.request(method, url, **httplib_request_kw)
  File "/usr/local/lib/python3.6/http/client.py", line 1291, in request
    self._send_request(method, url, body, headers, encode_chunked)
  File "/usr/local/lib/python3.6/http/client.py", line 1337, in _send_request
    self.endheaders(body, encode_chunked=encode_chunked)
  File "/usr/local/lib/python3.6/http/client.py", line 1286, in endheaders
    self._send_output(message_body, encode_chunked=encode_chunked)
  File "/usr/local/lib/python3.6/http/client.py", line 1046, in _send_output
    self.send(msg)
  File "/usr/local/lib/python3.6/http/client.py", line 984, in send
    self.connect()
  File "/home/airflow/.local/lib/python3.6/site-packages/urllib3/connection.py", line 187, in connect
    conn = self._new_conn()
  File "/home/airflow/.local/lib/python3.6/site-packages/urllib3/connection.py", line 172, in _new_conn
    self, "Failed to establish a new connection: %s" % e
urllib3.exceptions.NewConnectionError: <urllib3.connection.HTTPConnection object at 0x7fffafddc978>: Failed to establish a new connection: [Errno 111] Connection refused

During handling of the above exception, another exception occurred:

Traceback (most recent call last):
  File "/home/airflow/.local/lib/python3.6/site-packages/requests/adapters.py", line 449, in send
    timeout=timeout
  File "/home/airflow/.local/lib/python3.6/site-packages/urllib3/connectionpool.py", line 727, in urlopen
    method, url, error=e, _pool=self, _stacktrace=sys.exc_info()[2]
  File "/home/airflow/.local/lib/python3.6/site-packages/urllib3/util/retry.py", line 446, in increment
    raise MaxRetryError(_pool, url, error or ResponseError(cause))
urllib3.exceptions.MaxRetryError: HTTPConnectionPool(host='localhost', port=7010): Max retries exceeded with url: /extract_news (Caused by NewConnectionError('<urllib3.connection.HTTPConnection object at 0x7fffafddc978>: Failed to establish a new connection: [Errno 111] Connection refused',))

During handling of the above exception, another exception occurred:

Traceback (most recent call last):
  File "/home/airflow/.local/lib/python3.6/site-packages/airflow/models/taskinstance.py", line 1112, in _run_raw_task
    self._prepare_and_execute_task_with_callbacks(context, task)
  File "/home/airflow/.local/lib/python3.6/site-packages/airflow/models/taskinstance.py", line 1285, in _prepare_and_execute_task_with_callbacks
    result = self._execute_task(context, task_copy)
  File "/home/airflow/.local/lib/python3.6/site-packages/airflow/models/taskinstance.py", line 1315, in _execute_task
    result = task_copy.execute(context=context)
  File "/home/airflow/.local/lib/python3.6/site-packages/airflow/operators/python.py", line 117, in execute
    return_value = self.execute_callable()
  File "/home/airflow/.local/lib/python3.6/site-packages/airflow/operators/python.py", line 128, in execute_callable
    return self.python_callable(*self.op_args, **self.op_kwargs)
  File "/opt/airflow/dags/get_new_data.py", line 17, in scrap_cnn
    response = requests.get('http://localhost:7010/extract_news')
  File "/home/airflow/.local/lib/python3.6/site-packages/requests/api.py", line 76, in get
    return request('get', url, params=params, **kwargs)
  File "/home/airflow/.local/lib/python3.6/site-packages/requests/api.py", line 61, in request
    return session.request(method=method, url=url, **kwargs)
  File "/home/airflow/.local/lib/python3.6/site-packages/requests/sessions.py", line 542, in request
    resp = self.send(prep, **send_kwargs)
  File "/home/airflow/.local/lib/python3.6/site-packages/requests/sessions.py", line 655, in send
    r = adapter.send(request, **kwargs)
  File "/home/airflow/.local/lib/python3.6/site-packages/requests/adapters.py", line 516, in send
    raise ConnectionError(e, request=request)
requests.exceptions.ConnectionError: HTTPConnectionPool(host='localhost', port=7010): Max retries exceeded with url: /extract_news (Caused by NewConnectionError('<urllib3.connection.HTTPConnection object at 0x7fffafddc978>: Failed to establish a new connection: [Errno 111] Connection refused',))
[2024-05-26 16:21:01,874] {taskinstance.py:1503} INFO - Marking task as UP_FOR_RETRY. dag_id=get_new_data, task_id=scrap_cnn, execution_date=20240513T000000, start_date=20240526T162101, end_date=20240526T162101
[2024-05-26 16:21:01,924] {local_task_job.py:146} INFO - Task exited with return code 1
[2024-05-26 16:38:05,950] {taskinstance.py:851} INFO - Dependencies all met for <TaskInstance: get_new_data.scrap_cnn 2024-05-13T00:00:00+00:00 [queued]>
[2024-05-26 16:38:05,979] {taskinstance.py:851} INFO - Dependencies all met for <TaskInstance: get_new_data.scrap_cnn 2024-05-13T00:00:00+00:00 [queued]>
[2024-05-26 16:38:05,979] {taskinstance.py:1042} INFO - 
--------------------------------------------------------------------------------
[2024-05-26 16:38:05,980] {taskinstance.py:1043} INFO - Starting attempt 1 of 6
[2024-05-26 16:38:05,980] {taskinstance.py:1044} INFO - 
--------------------------------------------------------------------------------
[2024-05-26 16:38:06,004] {taskinstance.py:1063} INFO - Executing <Task(PythonOperator): scrap_cnn> on 2024-05-13T00:00:00+00:00
[2024-05-26 16:38:06,020] {standard_task_runner.py:52} INFO - Started process 194 to run task
[2024-05-26 16:38:06,032] {standard_task_runner.py:76} INFO - Running: ['airflow', 'tasks', 'run', 'get_new_data', 'scrap_cnn', '2024-05-13T00:00:00+00:00', '--job-id', '206', '--pool', 'default_pool', '--raw', '--subdir', 'DAGS_FOLDER/get_new_data.py', '--cfg-path', '/tmp/tmpp7vrtjf2', '--error-file', '/tmp/tmpvi612nwe']
[2024-05-26 16:38:06,045] {standard_task_runner.py:77} INFO - Job 206: Subtask scrap_cnn
[2024-05-26 16:38:06,132] {logging_mixin.py:104} INFO - Running <TaskInstance: get_new_data.scrap_cnn 2024-05-13T00:00:00+00:00 [running]> on host 6a7718113559
[2024-05-26 16:38:06,220] {taskinstance.py:1257} INFO - Exporting the following env vars:
AIRFLOW_CTX_DAG_OWNER=airflow
AIRFLOW_CTX_DAG_ID=get_new_data
AIRFLOW_CTX_TASK_ID=scrap_cnn
AIRFLOW_CTX_EXECUTION_DATE=2024-05-13T00:00:00+00:00
AIRFLOW_CTX_DAG_RUN_ID=scheduled__2024-05-13T00:00:00+00:00
[2024-05-26 16:53:25,345] {python.py:118} INFO - Done. Returned value was: None
[2024-05-26 16:53:25,354] {taskinstance.py:1166} INFO - Marking task as SUCCESS. dag_id=get_new_data, task_id=scrap_cnn, execution_date=20240513T000000, start_date=20240526T163805, end_date=20240526T165325
[2024-05-26 16:53:25,379] {taskinstance.py:1220} INFO - 1 downstream tasks scheduled from follow-on schedule check
[2024-05-26 16:53:25,423] {local_task_job.py:146} INFO - Task exited with return code 0
