[2024-05-26 16:32:53,897] {taskinstance.py:851} INFO - Dependencies all met for <TaskInstance: get_new_data.scrap_cnn 2024-05-19T00:00:00+00:00 [queued]>
[2024-05-26 16:32:53,933] {taskinstance.py:851} INFO - Dependencies all met for <TaskInstance: get_new_data.scrap_cnn 2024-05-19T00:00:00+00:00 [queued]>
[2024-05-26 16:32:53,937] {taskinstance.py:1042} INFO - 
--------------------------------------------------------------------------------
[2024-05-26 16:32:53,938] {taskinstance.py:1043} INFO - Starting attempt 1 of 6
[2024-05-26 16:32:53,939] {taskinstance.py:1044} INFO - 
--------------------------------------------------------------------------------
[2024-05-26 16:32:53,962] {taskinstance.py:1063} INFO - Executing <Task(PythonOperator): scrap_cnn> on 2024-05-19T00:00:00+00:00
[2024-05-26 16:32:53,969] {standard_task_runner.py:52} INFO - Started process 180 to run task
[2024-05-26 16:32:53,978] {standard_task_runner.py:76} INFO - Running: ['airflow', 'tasks', 'run', 'get_new_data', 'scrap_cnn', '2024-05-19T00:00:00+00:00', '--job-id', '180', '--pool', 'default_pool', '--raw', '--subdir', 'DAGS_FOLDER/get_new_data.py', '--cfg-path', '/tmp/tmp1uc7wzmy', '--error-file', '/tmp/tmp6ghpgb_j']
[2024-05-26 16:32:53,989] {standard_task_runner.py:77} INFO - Job 180: Subtask scrap_cnn
[2024-05-26 16:32:54,072] {logging_mixin.py:104} INFO - Running <TaskInstance: get_new_data.scrap_cnn 2024-05-19T00:00:00+00:00 [running]> on host 6a7718113559
[2024-05-26 16:32:54,129] {taskinstance.py:1257} INFO - Exporting the following env vars:
AIRFLOW_CTX_DAG_OWNER=airflow
AIRFLOW_CTX_DAG_ID=get_new_data
AIRFLOW_CTX_TASK_ID=scrap_cnn
AIRFLOW_CTX_EXECUTION_DATE=2024-05-19T00:00:00+00:00
AIRFLOW_CTX_DAG_RUN_ID=scheduled__2024-05-19T00:00:00+00:00
[2024-05-26 16:35:08,820] {local_task_job.py:77} ERROR - Received SIGTERM. Terminating subprocesses
[2024-05-26 16:35:09,098] {process_utils.py:100} INFO - Sending Signals.SIGTERM to GPID 180
[2024-05-26 16:35:09,148] {taskinstance.py:1239} ERROR - Received SIGTERM. Terminating subprocesses.
[2024-05-26 16:35:09,156] {logging_mixin.py:104} WARNING - --- Logging error ---
[2024-05-26 16:35:09,219] {logging_mixin.py:104} WARNING - Traceback (most recent call last):
[2024-05-26 16:35:09,235] {logging_mixin.py:104} WARNING -   File "/home/airflow/.local/lib/python3.6/site-packages/urllib3/connectionpool.py", line 677, in urlopen
    chunked=chunked,
[2024-05-26 16:35:09,237] {logging_mixin.py:104} WARNING -   File "/home/airflow/.local/lib/python3.6/site-packages/urllib3/connectionpool.py", line 426, in _make_request
    six.raise_from(e, None)
[2024-05-26 16:35:09,238] {logging_mixin.py:104} WARNING -   File "<string>", line 3, in raise_from
[2024-05-26 16:35:09,240] {logging_mixin.py:104} WARNING -   File "/home/airflow/.local/lib/python3.6/site-packages/urllib3/connectionpool.py", line 421, in _make_request
    httplib_response = conn.getresponse()
[2024-05-26 16:35:09,242] {logging_mixin.py:104} WARNING -   File "/usr/local/lib/python3.6/http/client.py", line 1383, in getresponse
    response.begin()
[2024-05-26 16:35:09,249] {logging_mixin.py:104} WARNING -   File "/usr/local/lib/python3.6/http/client.py", line 320, in begin
    version, status, reason = self._read_status()
[2024-05-26 16:35:09,250] {logging_mixin.py:104} WARNING -   File "/usr/local/lib/python3.6/http/client.py", line 289, in _read_status
    raise RemoteDisconnected("Remote end closed connection without"
[2024-05-26 16:35:09,252] {logging_mixin.py:104} WARNING - http.client.RemoteDisconnected: Remote end closed connection without response
[2024-05-26 16:35:09,254] {logging_mixin.py:104} WARNING - 
During handling of the above exception, another exception occurred:
[2024-05-26 16:35:09,255] {logging_mixin.py:104} WARNING - Traceback (most recent call last):
[2024-05-26 16:35:09,257] {logging_mixin.py:104} WARNING -   File "/home/airflow/.local/lib/python3.6/site-packages/requests/adapters.py", line 449, in send
    timeout=timeout
[2024-05-26 16:35:09,261] {logging_mixin.py:104} WARNING -   File "/home/airflow/.local/lib/python3.6/site-packages/urllib3/connectionpool.py", line 727, in urlopen
    method, url, error=e, _pool=self, _stacktrace=sys.exc_info()[2]
[2024-05-26 16:35:09,263] {logging_mixin.py:104} WARNING -   File "/home/airflow/.local/lib/python3.6/site-packages/urllib3/util/retry.py", line 410, in increment
    raise six.reraise(type(error), error, _stacktrace)
[2024-05-26 16:35:09,263] {logging_mixin.py:104} WARNING -   File "/home/airflow/.local/lib/python3.6/site-packages/urllib3/packages/six.py", line 734, in reraise
    raise value.with_traceback(tb)
[2024-05-26 16:35:09,266] {logging_mixin.py:104} WARNING -   File "/home/airflow/.local/lib/python3.6/site-packages/urllib3/connectionpool.py", line 677, in urlopen
    chunked=chunked,
[2024-05-26 16:35:09,268] {logging_mixin.py:104} WARNING -   File "/home/airflow/.local/lib/python3.6/site-packages/urllib3/connectionpool.py", line 426, in _make_request
    six.raise_from(e, None)
[2024-05-26 16:35:09,274] {logging_mixin.py:104} WARNING -   File "<string>", line 3, in raise_from
[2024-05-26 16:35:09,276] {logging_mixin.py:104} WARNING -   File "/home/airflow/.local/lib/python3.6/site-packages/urllib3/connectionpool.py", line 421, in _make_request
    httplib_response = conn.getresponse()
[2024-05-26 16:35:09,288] {logging_mixin.py:104} WARNING -   File "/usr/local/lib/python3.6/http/client.py", line 1383, in getresponse
    response.begin()
[2024-05-26 16:35:09,290] {logging_mixin.py:104} WARNING -   File "/usr/local/lib/python3.6/http/client.py", line 320, in begin
    version, status, reason = self._read_status()
[2024-05-26 16:35:09,299] {logging_mixin.py:104} WARNING -   File "/usr/local/lib/python3.6/http/client.py", line 289, in _read_status
    raise RemoteDisconnected("Remote end closed connection without"
[2024-05-26 16:35:09,311] {logging_mixin.py:104} WARNING - urllib3.exceptions.ProtocolError: ('Connection aborted.', RemoteDisconnected('Remote end closed connection without response',))
[2024-05-26 16:35:09,333] {logging_mixin.py:104} WARNING - 
During handling of the above exception, another exception occurred:
[2024-05-26 16:35:09,335] {logging_mixin.py:104} WARNING - Traceback (most recent call last):
[2024-05-26 16:35:09,338] {logging_mixin.py:104} WARNING -   File "/home/airflow/.local/lib/python3.6/site-packages/airflow/models/taskinstance.py", line 1112, in _run_raw_task
    self._prepare_and_execute_task_with_callbacks(context, task)
[2024-05-26 16:35:09,343] {logging_mixin.py:104} WARNING -   File "/home/airflow/.local/lib/python3.6/site-packages/airflow/models/taskinstance.py", line 1285, in _prepare_and_execute_task_with_callbacks
    result = self._execute_task(context, task_copy)
[2024-05-26 16:35:09,349] {logging_mixin.py:104} WARNING -   File "/home/airflow/.local/lib/python3.6/site-packages/airflow/models/taskinstance.py", line 1315, in _execute_task
    result = task_copy.execute(context=context)
[2024-05-26 16:35:09,350] {logging_mixin.py:104} WARNING -   File "/home/airflow/.local/lib/python3.6/site-packages/airflow/operators/python.py", line 117, in execute
    return_value = self.execute_callable()
[2024-05-26 16:35:09,352] {logging_mixin.py:104} WARNING -   File "/home/airflow/.local/lib/python3.6/site-packages/airflow/operators/python.py", line 128, in execute_callable
    return self.python_callable(*self.op_args, **self.op_kwargs)
[2024-05-26 16:35:09,354] {logging_mixin.py:104} WARNING -   File "/opt/airflow/dags/get_new_data.py", line 17, in scrap_cnn
    response = requests.get('http://cnn_scrapper:7010/extract_news')
[2024-05-26 16:35:09,357] {logging_mixin.py:104} WARNING -   File "/home/airflow/.local/lib/python3.6/site-packages/requests/api.py", line 76, in get
    return request('get', url, params=params, **kwargs)
[2024-05-26 16:35:09,362] {logging_mixin.py:104} WARNING -   File "/home/airflow/.local/lib/python3.6/site-packages/requests/api.py", line 61, in request
    return session.request(method=method, url=url, **kwargs)
[2024-05-26 16:35:09,364] {logging_mixin.py:104} WARNING -   File "/home/airflow/.local/lib/python3.6/site-packages/requests/sessions.py", line 542, in request
    resp = self.send(prep, **send_kwargs)
[2024-05-26 16:35:09,371] {logging_mixin.py:104} WARNING -   File "/home/airflow/.local/lib/python3.6/site-packages/requests/sessions.py", line 655, in send
    r = adapter.send(request, **kwargs)
[2024-05-26 16:35:09,376] {logging_mixin.py:104} WARNING -   File "/home/airflow/.local/lib/python3.6/site-packages/requests/adapters.py", line 498, in send
    raise ConnectionError(err, request=request)
[2024-05-26 16:35:09,382] {logging_mixin.py:104} WARNING - requests.exceptions.ConnectionError: ('Connection aborted.', RemoteDisconnected('Remote end closed connection without response',))
[2024-05-26 16:35:09,386] {logging_mixin.py:104} WARNING - 
During handling of the above exception, another exception occurred:
[2024-05-26 16:35:09,391] {logging_mixin.py:104} WARNING - Traceback (most recent call last):
[2024-05-26 16:35:09,394] {logging_mixin.py:104} WARNING -   File "/usr/local/lib/python3.6/logging/__init__.py", line 994, in emit
    msg = self.format(record)
[2024-05-26 16:35:09,397] {logging_mixin.py:104} WARNING -   File "/usr/local/lib/python3.6/logging/__init__.py", line 840, in format
    return fmt.format(record)
[2024-05-26 16:35:09,398] {logging_mixin.py:104} WARNING -   File "/usr/local/lib/python3.6/logging/__init__.py", line 585, in format
    record.exc_text = self.formatException(record.exc_info)
[2024-05-26 16:35:09,402] {logging_mixin.py:104} WARNING -   File "/usr/local/lib/python3.6/logging/__init__.py", line 535, in formatException
    traceback.print_exception(ei[0], ei[1], tb, None, sio)
[2024-05-26 16:35:09,405] {logging_mixin.py:104} WARNING -   File "/usr/local/lib/python3.6/traceback.py", line 104, in print_exception
    type(value), value, tb, limit=limit).format(chain=chain):
[2024-05-26 16:35:09,412] {logging_mixin.py:104} WARNING -   File "/usr/local/lib/python3.6/traceback.py", line 522, in __init__
    self._load_lines()
[2024-05-26 16:35:09,414] {logging_mixin.py:104} WARNING -   File "/usr/local/lib/python3.6/traceback.py", line 534, in _load_lines
    self.__context__._load_lines()
[2024-05-26 16:35:09,433] {logging_mixin.py:104} WARNING -   File "/usr/local/lib/python3.6/traceback.py", line 532, in _load_lines
    frame.line
[2024-05-26 16:35:09,441] {logging_mixin.py:104} WARNING -   File "/usr/local/lib/python3.6/traceback.py", line 286, in line
    self._line = linecache.getline(self.filename, self.lineno).strip()
[2024-05-26 16:35:09,444] {logging_mixin.py:104} WARNING -   File "/usr/local/lib/python3.6/linecache.py", line 16, in getline
    lines = getlines(filename, module_globals)
[2024-05-26 16:35:09,445] {logging_mixin.py:104} WARNING -   File "/usr/local/lib/python3.6/linecache.py", line 47, in getlines
    return updatecache(filename, module_globals)
[2024-05-26 16:35:09,448] {logging_mixin.py:104} WARNING -   File "/usr/local/lib/python3.6/linecache.py", line 137, in updatecache
    lines = fp.readlines()
[2024-05-26 16:35:09,450] {logging_mixin.py:104} WARNING -   File "/usr/local/lib/python3.6/codecs.py", line 318, in decode
    def decode(self, input, final=False):
[2024-05-26 16:35:09,457] {logging_mixin.py:104} WARNING -   File "/home/airflow/.local/lib/python3.6/site-packages/airflow/models/taskinstance.py", line 1241, in signal_handler
    raise AirflowException("Task received SIGTERM signal")
[2024-05-26 16:35:09,464] {logging_mixin.py:104} WARNING - airflow.exceptions.AirflowException: Task received SIGTERM signal
[2024-05-26 16:35:09,467] {logging_mixin.py:104} WARNING - Call stack:
[2024-05-26 16:35:09,479] {logging_mixin.py:104} WARNING -   File "/home/airflow/.local/bin/airflow", line 8, in <module>
    sys.exit(main())
[2024-05-26 16:35:09,480] {logging_mixin.py:104} WARNING -   File "/home/airflow/.local/lib/python3.6/site-packages/airflow/__main__.py", line 40, in main
    args.func(args)
[2024-05-26 16:35:09,482] {logging_mixin.py:104} WARNING -   File "/home/airflow/.local/lib/python3.6/site-packages/airflow/cli/cli_parser.py", line 48, in command
    return func(*args, **kwargs)
[2024-05-26 16:35:09,483] {logging_mixin.py:104} WARNING -   File "/home/airflow/.local/lib/python3.6/site-packages/airflow/utils/cli.py", line 89, in wrapper
    return f(*args, **kwargs)
[2024-05-26 16:35:09,487] {logging_mixin.py:104} WARNING -   File "/home/airflow/.local/lib/python3.6/site-packages/airflow/cli/commands/scheduler_command.py", line 63, in scheduler
    job.run()
[2024-05-26 16:35:09,488] {logging_mixin.py:104} WARNING -   File "/home/airflow/.local/lib/python3.6/site-packages/airflow/jobs/base_job.py", line 237, in run
    self._execute()
[2024-05-26 16:35:09,490] {logging_mixin.py:104} WARNING -   File "/home/airflow/.local/lib/python3.6/site-packages/airflow/jobs/scheduler_job.py", line 1272, in _execute
    self.executor.start()
[2024-05-26 16:35:09,494] {logging_mixin.py:104} WARNING -   File "/home/airflow/.local/lib/python3.6/site-packages/airflow/executors/local_executor.py", line 346, in start
    self.impl.start()
[2024-05-26 16:35:09,499] {logging_mixin.py:104} WARNING -   File "/home/airflow/.local/lib/python3.6/site-packages/airflow/executors/local_executor.py", line 291, in start
    worker.start()
[2024-05-26 16:35:09,501] {logging_mixin.py:104} WARNING -   File "/usr/local/lib/python3.6/multiprocessing/process.py", line 105, in start
    self._popen = self._Popen(self)
[2024-05-26 16:35:09,505] {logging_mixin.py:104} WARNING -   File "/usr/local/lib/python3.6/multiprocessing/context.py", line 223, in _Popen
    return _default_context.get_context().Process._Popen(process_obj)
[2024-05-26 16:35:09,507] {logging_mixin.py:104} WARNING -   File "/usr/local/lib/python3.6/multiprocessing/context.py", line 277, in _Popen
    return Popen(process_obj)
[2024-05-26 16:35:09,509] {logging_mixin.py:104} WARNING -   File "/usr/local/lib/python3.6/multiprocessing/popen_fork.py", line 19, in __init__
    self._launch(process_obj)
[2024-05-26 16:35:09,511] {logging_mixin.py:104} WARNING -   File "/usr/local/lib/python3.6/multiprocessing/popen_fork.py", line 73, in _launch
    code = process_obj._bootstrap()
[2024-05-26 16:35:09,512] {logging_mixin.py:104} WARNING -   File "/usr/local/lib/python3.6/multiprocessing/process.py", line 258, in _bootstrap
    self.run()
[2024-05-26 16:35:09,512] {logging_mixin.py:104} WARNING -   File "/home/airflow/.local/lib/python3.6/site-packages/airflow/executors/local_executor.py", line 69, in run
    return super().run()
[2024-05-26 16:35:09,514] {logging_mixin.py:104} WARNING -   File "/usr/local/lib/python3.6/multiprocessing/process.py", line 93, in run
    self._target(*self._args, **self._kwargs)
[2024-05-26 16:35:09,515] {logging_mixin.py:104} WARNING -   File "/home/airflow/.local/lib/python3.6/site-packages/airflow/executors/local_executor.py", line 181, in do_work
    self.execute_work(key=key, command=command)
[2024-05-26 16:35:09,515] {logging_mixin.py:104} WARNING -   File "/home/airflow/.local/lib/python3.6/site-packages/airflow/executors/local_executor.py", line 85, in execute_work
    state = self._execute_work_in_fork(command)
[2024-05-26 16:35:09,516] {logging_mixin.py:104} WARNING -   File "/home/airflow/.local/lib/python3.6/site-packages/airflow/executors/local_executor.py", line 123, in _execute_work_in_fork
    args.func(args)
[2024-05-26 16:35:09,517] {logging_mixin.py:104} WARNING -   File "/home/airflow/.local/lib/python3.6/site-packages/airflow/cli/cli_parser.py", line 48, in command
    return func(*args, **kwargs)
[2024-05-26 16:35:09,518] {logging_mixin.py:104} WARNING -   File "/home/airflow/.local/lib/python3.6/site-packages/airflow/utils/cli.py", line 89, in wrapper
    return f(*args, **kwargs)
[2024-05-26 16:35:09,519] {logging_mixin.py:104} WARNING -   File "/home/airflow/.local/lib/python3.6/site-packages/airflow/cli/commands/task_command.py", line 235, in task_run
    _run_task_by_selected_method(args, dag, ti)
[2024-05-26 16:35:09,520] {logging_mixin.py:104} WARNING -   File "/home/airflow/.local/lib/python3.6/site-packages/airflow/cli/commands/task_command.py", line 64, in _run_task_by_selected_method
    _run_task_by_local_task_job(args, ti)
[2024-05-26 16:35:09,521] {logging_mixin.py:104} WARNING -   File "/home/airflow/.local/lib/python3.6/site-packages/airflow/cli/commands/task_command.py", line 120, in _run_task_by_local_task_job
    run_job.run()
[2024-05-26 16:35:09,522] {logging_mixin.py:104} WARNING -   File "/home/airflow/.local/lib/python3.6/site-packages/airflow/jobs/base_job.py", line 237, in run
    self._execute()
[2024-05-26 16:35:09,524] {logging_mixin.py:104} WARNING -   File "/home/airflow/.local/lib/python3.6/site-packages/airflow/jobs/local_task_job.py", line 97, in _execute
    self.task_runner.start()
[2024-05-26 16:35:09,525] {logging_mixin.py:104} WARNING -   File "/home/airflow/.local/lib/python3.6/site-packages/airflow/task/task_runner/standard_task_runner.py", line 41, in start
    self.process = self._start_by_fork()
[2024-05-26 16:35:09,527] {logging_mixin.py:104} WARNING -   File "/home/airflow/.local/lib/python3.6/site-packages/airflow/task/task_runner/standard_task_runner.py", line 85, in _start_by_fork
    args.func(args, dag=self.dag)
[2024-05-26 16:35:09,529] {logging_mixin.py:104} WARNING -   File "/home/airflow/.local/lib/python3.6/site-packages/airflow/cli/cli_parser.py", line 48, in command
    return func(*args, **kwargs)
[2024-05-26 16:35:09,530] {logging_mixin.py:104} WARNING -   File "/home/airflow/.local/lib/python3.6/site-packages/airflow/utils/cli.py", line 89, in wrapper
    return f(*args, **kwargs)
[2024-05-26 16:35:09,532] {logging_mixin.py:104} WARNING -   File "/home/airflow/.local/lib/python3.6/site-packages/airflow/cli/commands/task_command.py", line 235, in task_run
    _run_task_by_selected_method(args, dag, ti)
[2024-05-26 16:35:09,535] {logging_mixin.py:104} WARNING -   File "/home/airflow/.local/lib/python3.6/site-packages/airflow/cli/commands/task_command.py", line 66, in _run_task_by_selected_method
    _run_raw_task(args, ti)
[2024-05-26 16:35:09,536] {logging_mixin.py:104} WARNING -   File "/home/airflow/.local/lib/python3.6/site-packages/airflow/cli/commands/task_command.py", line 152, in _run_raw_task
    error_file=args.error_file,
[2024-05-26 16:35:09,537] {logging_mixin.py:104} WARNING -   File "/home/airflow/.local/lib/python3.6/site-packages/airflow/utils/session.py", line 65, in wrapper
    return func(*args, session=session, **kwargs)
[2024-05-26 16:35:09,539] {logging_mixin.py:104} WARNING -   File "/home/airflow/.local/lib/python3.6/site-packages/airflow/models/taskinstance.py", line 1152, in _run_raw_task
    self.handle_failure(e, test_mode, error_file=error_file)
[2024-05-26 16:35:09,541] {logging_mixin.py:104} WARNING -   File "/home/airflow/.local/lib/python3.6/site-packages/airflow/utils/session.py", line 65, in wrapper
    return func(*args, session=session, **kwargs)
[2024-05-26 16:35:09,542] {logging_mixin.py:104} WARNING -   File "/home/airflow/.local/lib/python3.6/site-packages/airflow/models/taskinstance.py", line 1455, in handle_failure
    self.log.exception(error)
[2024-05-26 16:35:09,543] {logging_mixin.py:104} WARNING -   File "/usr/local/lib/python3.6/logging/__init__.py", line 1343, in exception
    self.error(msg, *args, exc_info=exc_info, **kwargs)
[2024-05-26 16:35:09,544] {logging_mixin.py:104} WARNING -   File "/usr/local/lib/python3.6/logging/__init__.py", line 1337, in error
    self._log(ERROR, msg, args, **kwargs)
[2024-05-26 16:35:09,546] {logging_mixin.py:104} WARNING -   File "/usr/local/lib/python3.6/logging/__init__.py", line 1444, in _log
    self.handle(record)
[2024-05-26 16:35:09,547] {logging_mixin.py:104} WARNING -   File "/usr/local/lib/python3.6/logging/__init__.py", line 1454, in handle
    self.callHandlers(record)
[2024-05-26 16:35:09,548] {logging_mixin.py:104} WARNING -   File "/usr/local/lib/python3.6/logging/__init__.py", line 1516, in callHandlers
    hdlr.handle(record)
[2024-05-26 16:35:09,551] {logging_mixin.py:104} WARNING -   File "/usr/local/lib/python3.6/logging/__init__.py", line 865, in handle
    self.emit(record)
[2024-05-26 16:35:09,553] {logging_mixin.py:104} WARNING -   File "/home/airflow/.local/lib/python3.6/site-packages/airflow/utils/log/file_task_handler.py", line 64, in emit
    self.handler.emit(record)
[2024-05-26 16:35:09,557] {logging_mixin.py:104} WARNING - Message: ConnectionError(ProtocolError('Connection aborted.', RemoteDisconnected('Remote end closed connection without response',)),)
Arguments: ()
[2024-05-26 16:35:09,567] {taskinstance.py:1503} INFO - Marking task as UP_FOR_RETRY. dag_id=get_new_data, task_id=scrap_cnn, execution_date=20240519T000000, start_date=20240526T163253, end_date=20240526T163509
[2024-05-26 16:35:09,671] {process_utils.py:66} INFO - Process psutil.Process(pid=180, status='terminated', exitcode=1, started='16:32:53') (180) terminated with exit code 1
[2024-05-26 17:11:09,787] {taskinstance.py:851} INFO - Dependencies all met for <TaskInstance: get_new_data.scrap_cnn 2024-05-19T00:00:00+00:00 [queued]>
[2024-05-26 17:11:09,822] {taskinstance.py:851} INFO - Dependencies all met for <TaskInstance: get_new_data.scrap_cnn 2024-05-19T00:00:00+00:00 [queued]>
[2024-05-26 17:11:09,829] {taskinstance.py:1042} INFO - 
--------------------------------------------------------------------------------
[2024-05-26 17:11:09,836] {taskinstance.py:1043} INFO - Starting attempt 1 of 6
[2024-05-26 17:11:09,851] {taskinstance.py:1044} INFO - 
--------------------------------------------------------------------------------
[2024-05-26 17:11:09,879] {taskinstance.py:1063} INFO - Executing <Task(PythonOperator): scrap_cnn> on 2024-05-19T00:00:00+00:00
[2024-05-26 17:11:09,885] {standard_task_runner.py:52} INFO - Started process 178 to run task
[2024-05-26 17:11:09,903] {standard_task_runner.py:76} INFO - Running: ['airflow', 'tasks', 'run', 'get_new_data', 'scrap_cnn', '2024-05-19T00:00:00+00:00', '--job-id', '316', '--pool', 'default_pool', '--raw', '--subdir', 'DAGS_FOLDER/get_new_data.py', '--cfg-path', '/tmp/tmpibbpl19r', '--error-file', '/tmp/tmp45y1sbga']
[2024-05-26 17:11:09,915] {standard_task_runner.py:77} INFO - Job 316: Subtask scrap_cnn
[2024-05-26 17:11:10,030] {logging_mixin.py:104} INFO - Running <TaskInstance: get_new_data.scrap_cnn 2024-05-19T00:00:00+00:00 [running]> on host 6a7718113559
[2024-05-26 17:11:10,120] {taskinstance.py:1257} INFO - Exporting the following env vars:
AIRFLOW_CTX_DAG_OWNER=airflow
AIRFLOW_CTX_DAG_ID=get_new_data
AIRFLOW_CTX_TASK_ID=scrap_cnn
AIRFLOW_CTX_EXECUTION_DATE=2024-05-19T00:00:00+00:00
AIRFLOW_CTX_DAG_RUN_ID=scheduled__2024-05-19T00:00:00+00:00
[2024-05-26 17:12:34,453] {local_task_job.py:77} ERROR - Received SIGTERM. Terminating subprocesses
[2024-05-26 17:12:34,597] {process_utils.py:100} INFO - Sending Signals.SIGTERM to GPID 178
[2024-05-26 17:12:34,818] {taskinstance.py:1239} ERROR - Received SIGTERM. Terminating subprocesses.
[2024-05-26 17:12:35,093] {taskinstance.py:1455} ERROR - Task received SIGTERM signal
Traceback (most recent call last):
  File "/home/airflow/.local/lib/python3.6/site-packages/airflow/models/taskinstance.py", line 1112, in _run_raw_task
    self._prepare_and_execute_task_with_callbacks(context, task)
  File "/home/airflow/.local/lib/python3.6/site-packages/airflow/models/taskinstance.py", line 1285, in _prepare_and_execute_task_with_callbacks
    result = self._execute_task(context, task_copy)
  File "/home/airflow/.local/lib/python3.6/site-packages/airflow/models/taskinstance.py", line 1315, in _execute_task
    result = task_copy.execute(context=context)
  File "/home/airflow/.local/lib/python3.6/site-packages/airflow/operators/python.py", line 117, in execute
    return_value = self.execute_callable()
  File "/home/airflow/.local/lib/python3.6/site-packages/airflow/operators/python.py", line 128, in execute_callable
    return self.python_callable(*self.op_args, **self.op_kwargs)
  File "/opt/airflow/dags/get_new_data.py", line 17, in scrap_cnn
    response = requests.get('http://cnn_scrapper:7010/extract_news')
  File "/home/airflow/.local/lib/python3.6/site-packages/requests/api.py", line 76, in get
    return request('get', url, params=params, **kwargs)
  File "/home/airflow/.local/lib/python3.6/site-packages/requests/api.py", line 61, in request
    return session.request(method=method, url=url, **kwargs)
  File "/home/airflow/.local/lib/python3.6/site-packages/requests/sessions.py", line 542, in request
    resp = self.send(prep, **send_kwargs)
  File "/home/airflow/.local/lib/python3.6/site-packages/requests/sessions.py", line 655, in send
    r = adapter.send(request, **kwargs)
  File "/home/airflow/.local/lib/python3.6/site-packages/requests/adapters.py", line 449, in send
    timeout=timeout
  File "/home/airflow/.local/lib/python3.6/site-packages/urllib3/connectionpool.py", line 677, in urlopen
    chunked=chunked,
  File "/home/airflow/.local/lib/python3.6/site-packages/urllib3/connectionpool.py", line 426, in _make_request
    six.raise_from(e, None)
  File "<string>", line 3, in raise_from
  File "/home/airflow/.local/lib/python3.6/site-packages/urllib3/connectionpool.py", line 421, in _make_request
    httplib_response = conn.getresponse()
  File "/usr/local/lib/python3.6/http/client.py", line 1383, in getresponse
    response.begin()
  File "/usr/local/lib/python3.6/http/client.py", line 320, in begin
    version, status, reason = self._read_status()
  File "/usr/local/lib/python3.6/http/client.py", line 281, in _read_status
    line = str(self.fp.readline(_MAXLINE + 1), "iso-8859-1")
  File "/usr/local/lib/python3.6/socket.py", line 586, in readinto
    return self._sock.recv_into(b)
  File "/home/airflow/.local/lib/python3.6/site-packages/airflow/models/taskinstance.py", line 1241, in signal_handler
    raise AirflowException("Task received SIGTERM signal")
airflow.exceptions.AirflowException: Task received SIGTERM signal
[2024-05-26 17:12:35,127] {taskinstance.py:1503} INFO - Marking task as UP_FOR_RETRY. dag_id=get_new_data, task_id=scrap_cnn, execution_date=20240519T000000, start_date=20240526T171109, end_date=20240526T171235
[2024-05-26 17:12:35,318] {process_utils.py:66} INFO - Process psutil.Process(pid=178, status='terminated', exitcode=1, started='17:11:08') (178) terminated with exit code 1
