[2024-05-26 16:06:01,424] {taskinstance.py:851} INFO - Dependencies all met for <TaskInstance: get_new_data.scrap_cnn 2024-05-14T00:00:00+00:00 [queued]>
[2024-05-26 16:06:01,432] {taskinstance.py:851} INFO - Dependencies all met for <TaskInstance: get_new_data.scrap_cnn 2024-05-14T00:00:00+00:00 [queued]>
[2024-05-26 16:06:01,432] {taskinstance.py:1042} INFO - 
--------------------------------------------------------------------------------
[2024-05-26 16:06:01,433] {taskinstance.py:1043} INFO - Starting attempt 1 of 6
[2024-05-26 16:06:01,433] {taskinstance.py:1044} INFO - 
--------------------------------------------------------------------------------
[2024-05-26 16:06:01,442] {taskinstance.py:1063} INFO - Executing <Task(PythonOperator): scrap_cnn> on 2024-05-14T00:00:00+00:00
[2024-05-26 16:06:01,445] {standard_task_runner.py:52} INFO - Started process 195 to run task
[2024-05-26 16:06:01,449] {standard_task_runner.py:76} INFO - Running: ['airflow', 'tasks', 'run', 'get_new_data', 'scrap_cnn', '2024-05-14T00:00:00+00:00', '--job-id', '26', '--pool', 'default_pool', '--raw', '--subdir', 'DAGS_FOLDER/get_new_data.py', '--cfg-path', '/tmp/tmpnjhui_4n', '--error-file', '/tmp/tmpf4v14dav']
[2024-05-26 16:06:01,455] {standard_task_runner.py:77} INFO - Job 26: Subtask scrap_cnn
[2024-05-26 16:06:01,491] {logging_mixin.py:104} INFO - Running <TaskInstance: get_new_data.scrap_cnn 2024-05-14T00:00:00+00:00 [running]> on host 6a7718113559
[2024-05-26 16:06:01,522] {taskinstance.py:1257} INFO - Exporting the following env vars:
AIRFLOW_CTX_DAG_OWNER=airflow
AIRFLOW_CTX_DAG_ID=get_new_data
AIRFLOW_CTX_TASK_ID=scrap_cnn
AIRFLOW_CTX_EXECUTION_DATE=2024-05-14T00:00:00+00:00
AIRFLOW_CTX_DAG_RUN_ID=scheduled__2024-05-14T00:00:00+00:00
[2024-05-26 16:06:01,531] {taskinstance.py:1455} ERROR - HTTPConnectionPool(host='localhost', port=7010): Max retries exceeded with url: /extract_news (Caused by NewConnectionError('<urllib3.connection.HTTPConnection object at 0x7fffafdde978>: Failed to establish a new connection: [Errno 111] Connection refused',))
Traceback (most recent call last):
  File "/home/airflow/.local/lib/python3.6/site-packages/urllib3/connection.py", line 160, in _new_conn
    (self._dns_host, self.port), self.timeout, **extra_kw
  File "/home/airflow/.local/lib/python3.6/site-packages/urllib3/util/connection.py", line 84, in create_connection
    raise err
  File "/home/airflow/.local/lib/python3.6/site-packages/urllib3/util/connection.py", line 74, in create_connection
    sock.connect(sa)
ConnectionRefusedError: [Errno 111] Connection refused

During handling of the above exception, another exception occurred:

Traceback (most recent call last):
  File "/home/airflow/.local/lib/python3.6/site-packages/urllib3/connectionpool.py", line 677, in urlopen
    chunked=chunked,
  File "/home/airflow/.local/lib/python3.6/site-packages/urllib3/connectionpool.py", line 392, in _make_request
    conn.request(method, url, **httplib_request_kw)
  File "/usr/local/lib/python3.6/http/client.py", line 1291, in request
    self._send_request(method, url, body, headers, encode_chunked)
  File "/usr/local/lib/python3.6/http/client.py", line 1337, in _send_request
    self.endheaders(body, encode_chunked=encode_chunked)
  File "/usr/local/lib/python3.6/http/client.py", line 1286, in endheaders
    self._send_output(message_body, encode_chunked=encode_chunked)
  File "/usr/local/lib/python3.6/http/client.py", line 1046, in _send_output
    self.send(msg)
  File "/usr/local/lib/python3.6/http/client.py", line 984, in send
    self.connect()
  File "/home/airflow/.local/lib/python3.6/site-packages/urllib3/connection.py", line 187, in connect
    conn = self._new_conn()
  File "/home/airflow/.local/lib/python3.6/site-packages/urllib3/connection.py", line 172, in _new_conn
    self, "Failed to establish a new connection: %s" % e
urllib3.exceptions.NewConnectionError: <urllib3.connection.HTTPConnection object at 0x7fffafdde978>: Failed to establish a new connection: [Errno 111] Connection refused

During handling of the above exception, another exception occurred:

Traceback (most recent call last):
  File "/home/airflow/.local/lib/python3.6/site-packages/requests/adapters.py", line 449, in send
    timeout=timeout
  File "/home/airflow/.local/lib/python3.6/site-packages/urllib3/connectionpool.py", line 727, in urlopen
    method, url, error=e, _pool=self, _stacktrace=sys.exc_info()[2]
  File "/home/airflow/.local/lib/python3.6/site-packages/urllib3/util/retry.py", line 446, in increment
    raise MaxRetryError(_pool, url, error or ResponseError(cause))
urllib3.exceptions.MaxRetryError: HTTPConnectionPool(host='localhost', port=7010): Max retries exceeded with url: /extract_news (Caused by NewConnectionError('<urllib3.connection.HTTPConnection object at 0x7fffafdde978>: Failed to establish a new connection: [Errno 111] Connection refused',))

During handling of the above exception, another exception occurred:

Traceback (most recent call last):
  File "/home/airflow/.local/lib/python3.6/site-packages/airflow/models/taskinstance.py", line 1112, in _run_raw_task
    self._prepare_and_execute_task_with_callbacks(context, task)
  File "/home/airflow/.local/lib/python3.6/site-packages/airflow/models/taskinstance.py", line 1285, in _prepare_and_execute_task_with_callbacks
    result = self._execute_task(context, task_copy)
  File "/home/airflow/.local/lib/python3.6/site-packages/airflow/models/taskinstance.py", line 1315, in _execute_task
    result = task_copy.execute(context=context)
  File "/home/airflow/.local/lib/python3.6/site-packages/airflow/operators/python.py", line 117, in execute
    return_value = self.execute_callable()
  File "/home/airflow/.local/lib/python3.6/site-packages/airflow/operators/python.py", line 128, in execute_callable
    return self.python_callable(*self.op_args, **self.op_kwargs)
  File "/opt/airflow/dags/get_new_data.py", line 17, in scrap_cnn
    response = requests.get('http://localhost:7010/extract_news')
  File "/home/airflow/.local/lib/python3.6/site-packages/requests/api.py", line 76, in get
    return request('get', url, params=params, **kwargs)
  File "/home/airflow/.local/lib/python3.6/site-packages/requests/api.py", line 61, in request
    return session.request(method=method, url=url, **kwargs)
  File "/home/airflow/.local/lib/python3.6/site-packages/requests/sessions.py", line 542, in request
    resp = self.send(prep, **send_kwargs)
  File "/home/airflow/.local/lib/python3.6/site-packages/requests/sessions.py", line 655, in send
    r = adapter.send(request, **kwargs)
  File "/home/airflow/.local/lib/python3.6/site-packages/requests/adapters.py", line 516, in send
    raise ConnectionError(e, request=request)
requests.exceptions.ConnectionError: HTTPConnectionPool(host='localhost', port=7010): Max retries exceeded with url: /extract_news (Caused by NewConnectionError('<urllib3.connection.HTTPConnection object at 0x7fffafdde978>: Failed to establish a new connection: [Errno 111] Connection refused',))
[2024-05-26 16:06:01,536] {taskinstance.py:1503} INFO - Marking task as UP_FOR_RETRY. dag_id=get_new_data, task_id=scrap_cnn, execution_date=20240514T000000, start_date=20240526T160601, end_date=20240526T160601
[2024-05-26 16:06:01,590] {local_task_job.py:146} INFO - Task exited with return code 1
[2024-05-26 16:21:01,850] {taskinstance.py:851} INFO - Dependencies all met for <TaskInstance: get_new_data.scrap_cnn 2024-05-14T00:00:00+00:00 [queued]>
[2024-05-26 16:21:01,861] {taskinstance.py:851} INFO - Dependencies all met for <TaskInstance: get_new_data.scrap_cnn 2024-05-14T00:00:00+00:00 [queued]>
[2024-05-26 16:21:01,863] {taskinstance.py:1042} INFO - 
--------------------------------------------------------------------------------
[2024-05-26 16:21:01,863] {taskinstance.py:1043} INFO - Starting attempt 1 of 6
[2024-05-26 16:21:01,864] {taskinstance.py:1044} INFO - 
--------------------------------------------------------------------------------
[2024-05-26 16:21:01,874] {taskinstance.py:1063} INFO - Executing <Task(PythonOperator): scrap_cnn> on 2024-05-14T00:00:00+00:00
[2024-05-26 16:21:01,877] {standard_task_runner.py:52} INFO - Started process 200 to run task
[2024-05-26 16:21:01,881] {standard_task_runner.py:76} INFO - Running: ['airflow', 'tasks', 'run', 'get_new_data', 'scrap_cnn', '2024-05-14T00:00:00+00:00', '--job-id', '110', '--pool', 'default_pool', '--raw', '--subdir', 'DAGS_FOLDER/get_new_data.py', '--cfg-path', '/tmp/tmpt6_cqds7', '--error-file', '/tmp/tmp9w20yito']
[2024-05-26 16:21:01,883] {standard_task_runner.py:77} INFO - Job 110: Subtask scrap_cnn
[2024-05-26 16:21:01,914] {logging_mixin.py:104} INFO - Running <TaskInstance: get_new_data.scrap_cnn 2024-05-14T00:00:00+00:00 [running]> on host 6a7718113559
[2024-05-26 16:21:01,948] {taskinstance.py:1257} INFO - Exporting the following env vars:
AIRFLOW_CTX_DAG_OWNER=airflow
AIRFLOW_CTX_DAG_ID=get_new_data
AIRFLOW_CTX_TASK_ID=scrap_cnn
AIRFLOW_CTX_EXECUTION_DATE=2024-05-14T00:00:00+00:00
AIRFLOW_CTX_DAG_RUN_ID=scheduled__2024-05-14T00:00:00+00:00
[2024-05-26 16:21:01,959] {taskinstance.py:1455} ERROR - HTTPConnectionPool(host='localhost', port=7010): Max retries exceeded with url: /extract_news (Caused by NewConnectionError('<urllib3.connection.HTTPConnection object at 0x7fffafddc9e8>: Failed to establish a new connection: [Errno 111] Connection refused',))
Traceback (most recent call last):
  File "/home/airflow/.local/lib/python3.6/site-packages/urllib3/connection.py", line 160, in _new_conn
    (self._dns_host, self.port), self.timeout, **extra_kw
  File "/home/airflow/.local/lib/python3.6/site-packages/urllib3/util/connection.py", line 84, in create_connection
    raise err
  File "/home/airflow/.local/lib/python3.6/site-packages/urllib3/util/connection.py", line 74, in create_connection
    sock.connect(sa)
ConnectionRefusedError: [Errno 111] Connection refused

During handling of the above exception, another exception occurred:

Traceback (most recent call last):
  File "/home/airflow/.local/lib/python3.6/site-packages/urllib3/connectionpool.py", line 677, in urlopen
    chunked=chunked,
  File "/home/airflow/.local/lib/python3.6/site-packages/urllib3/connectionpool.py", line 392, in _make_request
    conn.request(method, url, **httplib_request_kw)
  File "/usr/local/lib/python3.6/http/client.py", line 1291, in request
    self._send_request(method, url, body, headers, encode_chunked)
  File "/usr/local/lib/python3.6/http/client.py", line 1337, in _send_request
    self.endheaders(body, encode_chunked=encode_chunked)
  File "/usr/local/lib/python3.6/http/client.py", line 1286, in endheaders
    self._send_output(message_body, encode_chunked=encode_chunked)
  File "/usr/local/lib/python3.6/http/client.py", line 1046, in _send_output
    self.send(msg)
  File "/usr/local/lib/python3.6/http/client.py", line 984, in send
    self.connect()
  File "/home/airflow/.local/lib/python3.6/site-packages/urllib3/connection.py", line 187, in connect
    conn = self._new_conn()
  File "/home/airflow/.local/lib/python3.6/site-packages/urllib3/connection.py", line 172, in _new_conn
    self, "Failed to establish a new connection: %s" % e
urllib3.exceptions.NewConnectionError: <urllib3.connection.HTTPConnection object at 0x7fffafddc9e8>: Failed to establish a new connection: [Errno 111] Connection refused

During handling of the above exception, another exception occurred:

Traceback (most recent call last):
  File "/home/airflow/.local/lib/python3.6/site-packages/requests/adapters.py", line 449, in send
    timeout=timeout
  File "/home/airflow/.local/lib/python3.6/site-packages/urllib3/connectionpool.py", line 727, in urlopen
    method, url, error=e, _pool=self, _stacktrace=sys.exc_info()[2]
  File "/home/airflow/.local/lib/python3.6/site-packages/urllib3/util/retry.py", line 446, in increment
    raise MaxRetryError(_pool, url, error or ResponseError(cause))
urllib3.exceptions.MaxRetryError: HTTPConnectionPool(host='localhost', port=7010): Max retries exceeded with url: /extract_news (Caused by NewConnectionError('<urllib3.connection.HTTPConnection object at 0x7fffafddc9e8>: Failed to establish a new connection: [Errno 111] Connection refused',))

During handling of the above exception, another exception occurred:

Traceback (most recent call last):
  File "/home/airflow/.local/lib/python3.6/site-packages/airflow/models/taskinstance.py", line 1112, in _run_raw_task
    self._prepare_and_execute_task_with_callbacks(context, task)
  File "/home/airflow/.local/lib/python3.6/site-packages/airflow/models/taskinstance.py", line 1285, in _prepare_and_execute_task_with_callbacks
    result = self._execute_task(context, task_copy)
  File "/home/airflow/.local/lib/python3.6/site-packages/airflow/models/taskinstance.py", line 1315, in _execute_task
    result = task_copy.execute(context=context)
  File "/home/airflow/.local/lib/python3.6/site-packages/airflow/operators/python.py", line 117, in execute
    return_value = self.execute_callable()
  File "/home/airflow/.local/lib/python3.6/site-packages/airflow/operators/python.py", line 128, in execute_callable
    return self.python_callable(*self.op_args, **self.op_kwargs)
  File "/opt/airflow/dags/get_new_data.py", line 17, in scrap_cnn
    response = requests.get('http://localhost:7010/extract_news')
  File "/home/airflow/.local/lib/python3.6/site-packages/requests/api.py", line 76, in get
    return request('get', url, params=params, **kwargs)
  File "/home/airflow/.local/lib/python3.6/site-packages/requests/api.py", line 61, in request
    return session.request(method=method, url=url, **kwargs)
  File "/home/airflow/.local/lib/python3.6/site-packages/requests/sessions.py", line 542, in request
    resp = self.send(prep, **send_kwargs)
  File "/home/airflow/.local/lib/python3.6/site-packages/requests/sessions.py", line 655, in send
    r = adapter.send(request, **kwargs)
  File "/home/airflow/.local/lib/python3.6/site-packages/requests/adapters.py", line 516, in send
    raise ConnectionError(e, request=request)
requests.exceptions.ConnectionError: HTTPConnectionPool(host='localhost', port=7010): Max retries exceeded with url: /extract_news (Caused by NewConnectionError('<urllib3.connection.HTTPConnection object at 0x7fffafddc9e8>: Failed to establish a new connection: [Errno 111] Connection refused',))
[2024-05-26 16:21:01,964] {taskinstance.py:1503} INFO - Marking task as UP_FOR_RETRY. dag_id=get_new_data, task_id=scrap_cnn, execution_date=20240514T000000, start_date=20240526T162101, end_date=20240526T162101
[2024-05-26 16:21:02,019] {local_task_job.py:146} INFO - Task exited with return code 1
[2024-05-26 16:38:06,060] {taskinstance.py:851} INFO - Dependencies all met for <TaskInstance: get_new_data.scrap_cnn 2024-05-14T00:00:00+00:00 [queued]>
[2024-05-26 16:38:06,078] {taskinstance.py:851} INFO - Dependencies all met for <TaskInstance: get_new_data.scrap_cnn 2024-05-14T00:00:00+00:00 [queued]>
[2024-05-26 16:38:06,079] {taskinstance.py:1042} INFO - 
--------------------------------------------------------------------------------
[2024-05-26 16:38:06,080] {taskinstance.py:1043} INFO - Starting attempt 1 of 6
[2024-05-26 16:38:06,082] {taskinstance.py:1044} INFO - 
--------------------------------------------------------------------------------
[2024-05-26 16:38:06,107] {taskinstance.py:1063} INFO - Executing <Task(PythonOperator): scrap_cnn> on 2024-05-14T00:00:00+00:00
[2024-05-26 16:38:06,116] {standard_task_runner.py:52} INFO - Started process 199 to run task
[2024-05-26 16:38:06,118] {standard_task_runner.py:76} INFO - Running: ['airflow', 'tasks', 'run', 'get_new_data', 'scrap_cnn', '2024-05-14T00:00:00+00:00', '--job-id', '210', '--pool', 'default_pool', '--raw', '--subdir', 'DAGS_FOLDER/get_new_data.py', '--cfg-path', '/tmp/tmps0o9xk15', '--error-file', '/tmp/tmpxcrur0__']
[2024-05-26 16:38:06,123] {standard_task_runner.py:77} INFO - Job 210: Subtask scrap_cnn
[2024-05-26 16:38:06,190] {logging_mixin.py:104} INFO - Running <TaskInstance: get_new_data.scrap_cnn 2024-05-14T00:00:00+00:00 [running]> on host 6a7718113559
[2024-05-26 16:38:06,300] {taskinstance.py:1257} INFO - Exporting the following env vars:
AIRFLOW_CTX_DAG_OWNER=airflow
AIRFLOW_CTX_DAG_ID=get_new_data
AIRFLOW_CTX_TASK_ID=scrap_cnn
AIRFLOW_CTX_EXECUTION_DATE=2024-05-14T00:00:00+00:00
AIRFLOW_CTX_DAG_RUN_ID=scheduled__2024-05-14T00:00:00+00:00
[2024-05-26 16:53:20,720] {python.py:118} INFO - Done. Returned value was: None
[2024-05-26 16:53:20,730] {taskinstance.py:1166} INFO - Marking task as SUCCESS. dag_id=get_new_data, task_id=scrap_cnn, execution_date=20240514T000000, start_date=20240526T163806, end_date=20240526T165320
[2024-05-26 16:53:20,755] {taskinstance.py:1220} INFO - 1 downstream tasks scheduled from follow-on schedule check
[2024-05-26 16:53:20,782] {local_task_job.py:146} INFO - Task exited with return code 0
