[2024-05-26 16:55:34,121] {taskinstance.py:851} INFO - Dependencies all met for <TaskInstance: get_new_data.transform 2024-05-09T00:00:00+00:00 [queued]>
[2024-05-26 16:55:34,163] {taskinstance.py:851} INFO - Dependencies all met for <TaskInstance: get_new_data.transform 2024-05-09T00:00:00+00:00 [queued]>
[2024-05-26 16:55:34,164] {taskinstance.py:1042} INFO - 
--------------------------------------------------------------------------------
[2024-05-26 16:55:34,164] {taskinstance.py:1043} INFO - Starting attempt 2 of 6
[2024-05-26 16:55:34,165] {taskinstance.py:1044} INFO - 
--------------------------------------------------------------------------------
[2024-05-26 16:55:34,181] {taskinstance.py:1063} INFO - Executing <Task(PythonOperator): transform> on 2024-05-09T00:00:00+00:00
[2024-05-26 16:55:34,187] {standard_task_runner.py:52} INFO - Started process 426 to run task
[2024-05-26 16:55:34,201] {standard_task_runner.py:76} INFO - Running: ['airflow', 'tasks', 'run', 'get_new_data', 'transform', '2024-05-09T00:00:00+00:00', '--job-id', '240', '--pool', 'default_pool', '--raw', '--subdir', 'DAGS_FOLDER/get_new_data.py', '--cfg-path', '/tmp/tmphzx7i3dv', '--error-file', '/tmp/tmpqykrbfs8']
[2024-05-26 16:55:34,204] {standard_task_runner.py:77} INFO - Job 240: Subtask transform
[2024-05-26 16:55:34,256] {logging_mixin.py:104} INFO - Running <TaskInstance: get_new_data.transform 2024-05-09T00:00:00+00:00 [running]> on host 6a7718113559
[2024-05-26 16:55:34,290] {taskinstance.py:1257} INFO - Exporting the following env vars:
AIRFLOW_CTX_DAG_OWNER=airflow
AIRFLOW_CTX_DAG_ID=get_new_data
AIRFLOW_CTX_TASK_ID=transform
AIRFLOW_CTX_EXECUTION_DATE=2024-05-09T00:00:00+00:00
AIRFLOW_CTX_DAG_RUN_ID=scheduled__2024-05-09T00:00:00+00:00
[2024-05-26 16:55:34,380] {taskinstance.py:1455} ERROR - Expecting value: line 1 column 1 (char 0)
Traceback (most recent call last):
  File "/home/airflow/.local/lib/python3.6/site-packages/airflow/models/taskinstance.py", line 1112, in _run_raw_task
    self._prepare_and_execute_task_with_callbacks(context, task)
  File "/home/airflow/.local/lib/python3.6/site-packages/airflow/models/taskinstance.py", line 1285, in _prepare_and_execute_task_with_callbacks
    result = self._execute_task(context, task_copy)
  File "/home/airflow/.local/lib/python3.6/site-packages/airflow/models/taskinstance.py", line 1315, in _execute_task
    result = task_copy.execute(context=context)
  File "/home/airflow/.local/lib/python3.6/site-packages/airflow/operators/python.py", line 117, in execute
    return_value = self.execute_callable()
  File "/home/airflow/.local/lib/python3.6/site-packages/airflow/operators/python.py", line 128, in execute_callable
    return self.python_callable(*self.op_args, **self.op_kwargs)
  File "/opt/airflow/dags/get_new_data.py", line 38, in transform
    transformed_data = response.json()['data']
  File "/home/airflow/.local/lib/python3.6/site-packages/requests/models.py", line 900, in json
    return complexjson.loads(self.text, **kwargs)
  File "/usr/local/lib/python3.6/json/__init__.py", line 354, in loads
    return _default_decoder.decode(s)
  File "/usr/local/lib/python3.6/json/decoder.py", line 339, in decode
    obj, end = self.raw_decode(s, idx=_w(s, 0).end())
  File "/usr/local/lib/python3.6/json/decoder.py", line 357, in raw_decode
    raise JSONDecodeError("Expecting value", s, err.value) from None
json.decoder.JSONDecodeError: Expecting value: line 1 column 1 (char 0)
[2024-05-26 16:55:34,386] {taskinstance.py:1503} INFO - Marking task as UP_FOR_RETRY. dag_id=get_new_data, task_id=transform, execution_date=20240509T000000, start_date=20240526T165534, end_date=20240526T165534
[2024-05-26 16:55:34,512] {local_task_job.py:146} INFO - Task exited with return code 1
